Workbook
Name Acreditado_Obs1: 'Tarifas (2)'!$C$7:$C$17
Name Acreditado_Obs1: Tarifas!$C$7:$C$25
Name No_Acreditado: 'Tarifas (2)'!$C$18:$C$105
Name No_Acreditado: Tarifas!$C$26:$C$107

Sheet Cotización V009
A1: UNIVERSIDAD SANTIAGO DE CALI DIRECCIÓN GENERAL DE LABORATORIOS LABORATORIO DE METROLOGÍA Calle 5ª Carrera 62 Campus Pampalinda Bloque 4 Piso 1 Laboratorio 4129 PBX: 5183000 Ext. 9093 E-mail: comercialmetrologia@usc.edu.co
A2: COTIZACIÓN DE SERVICIOS DE CALIBRACIÓN
A3: R-CM003 / Versión 9 2024/09/17
A4: Tenemos el gusto de presentarle nuestra propuesta económica para la calibración de equipos
A5: No. Cotización: | B5: 26-1241A
A6: Fecha: | B6: 46056
A7: Empresa: | B7: Aldeas Infantiles | E7: Nit: | F7: N.I
A8: Ciudad | B8: Cali | E8: Teléfono: | F8: 300 2584998
A9: Contacto: | B9: David Rendon | E9: Email: | F9: david.rendon@aldeasinfantiles.org.co
A11: Equipo / Número de puntos | B11: Tipo de servicio | C11: Magnitud | E11: Norma / Guía Técnica | F11: Cantidad | G11: Valor Unitario | H11: Valor Total
A12: Termómetros digitales con sensor termopar, RTD, termómetros digitales con sonda o punzón - 30 °C ≤ t ≤ 150 °C (Incluye 3 puntos de calibración) | B12: Acreditado_Obs1 | C12: =IF(B12="","",VLOOKUP(A12,Tarifas!$C$7:$G$108,2,FALSE)) -> Temperatura | E12: =IF(B12="","",VLOOKUP(A12,Tarifas!$C$7:$E$108,3,FALSE)) -> Procedimiento TH-001 para la calibración de termómetros digitales (de lectura directa) por comparación, Centro Español de Metrología, edición digital 2.2021 | F12: 4 | G12: =IF(B12="","",VLOOKUP(A12,Tarifas!$C$7:$H$107,6,FALSE)) -> 156600 | H12: =IF(B12="","",G12*F12) -> 626400
C13: =IF(B13="","",VLOOKUP(A13,Tarifas!$C$8:$G$107,2,FALSE)) | E13: =IF(B13="","",VLOOKUP(A13,Tarifas!$C$7:$E$108,3,FALSE)) | G13: =IF(B13="","",VLOOKUP(A13,Tarifas!$C$6:$H$107,6,FALSE)) | H13: =IF(B13="","",G13*F13)
C14: =IF(B14="","",VLOOKUP(A14,Tarifas!$C$8:$G$107,2,FALSE)) | E14: =IF(B14="","",VLOOKUP(A14,Tarifas!$C$7:$E$108,3,FALSE)) | G14: =IF(B14="","",VLOOKUP(A14,Tarifas!$C$6:$H$107,6,FALSE)) | H14: =IF(B14="","",G14*F14)
C15: =IF(B15="","",VLOOKUP(A15,Tarifas!$C$8:$G$107,2,FALSE)) | E15: =IF(B15="","",VLOOKUP(A15,Tarifas!$C$7:$E$108,3,FALSE)) | G15: =IF(B15="","",VLOOKUP(A15,Tarifas!$C$6:$H$107,6,FALSE)) | H15: =IF(B15="","",G15*F15)
C16: =IF(B16="","",VLOOKUP(A16,Tarifas!$C$8:$G$107,2,FALSE)) | E16: =IF(B16="","",VLOOKUP(A16,Tarifas!$C$7:$E$108,3,FALSE)) | G16: =IF(B16="","",VLOOKUP(A16,Tarifas!$C$6:$H$107,6,FALSE)) | H16: =IF(B16="","",G16*F16)
C17: =IF(B17="","",VLOOKUP(A17,Tarifas!$C$8:$G$107,2,FALSE)) | E17: =IF(B17="","",VLOOKUP(A17,Tarifas!$C$7:$E$108,3,FALSE)) | G17: =IF(B17="","",VLOOKUP(A17,Tarifas!$C$6:$H$107,6,FALSE)) | H17: =IF(B17="","",G17*F17)
C18: =IF(B18="","",VLOOKUP(A18,Tarifas!$C$8:$G$107,2,FALSE)) | E18: =IF(B18="","",VLOOKUP(A18,Tarifas!$C$7:$E$108,3,FALSE)) | G18: =IF(B18="","",VLOOKUP(A18,Tarifas!$C$6:$H$107,6,FALSE)) | H18: =IF(B18="","",G18*F18)
C19: =IF(B19="","",VLOOKUP(A19,Tarifas!$C$8:$G$107,2,FALSE)) | E19: =IF(B19="","",VLOOKUP(A19,Tarifas!$C$7:$E$108,3,FALSE)) | G19: =IF(B19="","",VLOOKUP(A19,Tarifas!$C$6:$H$107,6,FALSE)) | H19: =IF(B19="","",G19*F19)
C20: =IF(B20="","",VLOOKUP(A20,Tarifas!$C$8:$G$107,2,FALSE)) | E20: =IF(B20="","",VLOOKUP(A20,Tarifas!$C$7:$E$108,3,FALSE)) | G20: =IF(B20="","",VLOOKUP(A20,Tarifas!$C$6:$H$107,6,FALSE)) | H20: =IF(B20="","",G20*F20)
C21: =IF(B21="","",VLOOKUP(A21,Tarifas!$C$8:$G$107,2,FALSE)) | E21: =IF(B21="","",VLOOKUP(A21,Tarifas!$C$7:$E$108,3,FALSE)) | G21: =IF(B21="","",VLOOKUP(A21,Tarifas!$C$6:$H$107,6,FALSE)) | H21: =IF(B21="","",G21*F21)
C22: =IF(B22="","",VLOOKUP(A22,Tarifas!$C$8:$G$107,2,FALSE)) | E22: =IF(B22="","",VLOOKUP(A22,Tarifas!$C$7:$E$108,3,FALSE)) | G22: =IF(B22="","",VLOOKUP(A22,Tarifas!$C$6:$H$107,6,FALSE)) | H22: =IF(B22="","",G22*F22)
C23: =IF(B23="","",VLOOKUP(A23,Tarifas!$C$8:$G$107,2,FALSE)) | E23: =IF(B23="","",VLOOKUP(A23,Tarifas!$C$7:$E$108,3,FALSE)) | G23: =IF(B23="","",VLOOKUP(A23,Tarifas!$C$6:$H$107,6,FALSE)) | H23: =IF(B23="","",G23*F23)
C24: =IF(B24="","",VLOOKUP(A24,Tarifas!$C$8:$G$107,2,FALSE)) | E24: =IF(B24="","",VLOOKUP(A24,Tarifas!$C$7:$E$108,3,FALSE)) | G24: =IF(B24="","",VLOOKUP(A24,Tarifas!$C$6:$H$107,6,FALSE)) | H24: =IF(B24="","",G24*F24)
... C47: =IF(B47="","",VLOOKUP(A47,Tarifas!$C$8:$G$107,2,FALSE)) | E47: =IF(B47="","",VLOOKUP(A47,Tarifas!$C$7:$E$108,3,FALSE)) | G47: =IF(B47="","",VLOOKUP(A47,Tarifas!$C$6:$H$107,6,FALSE)) | H47: =IF(B47="","",G47*F47)
E49: Total de Servicio | F49: =SUM(F12:F47) -> 4 | G49: =SUM(H12:H47) -> 626400
E50: Descuento (%) | H50: =G49*F50 -> 0 | L50: Método de pago: 60 Dias
E51: Viáticos | L51: Método de pago: 30 Dias
E52: TOTAL | H52: =G49-H50+F51 -> 626400 | L52: Método de pago: Contado
A54: Acreditado_Obs1: El laboratorio de Metrología de la universidad Santiago de Cali cuenta con acreditación ONAC vigente a la fecha, con código de acreditación 20-LAC-021, bajo la norma ISO/IEC17025:2017 en las magnitudes de Presion, Masa (Instrumentos de pesaje), Temperatura en inmersión, temperatura y Humedad en condiciones ambietales.
A56: Condiciones Comerciales y Técnicas
A57: Método de pago: 30 Dias
A58: Tener presente que: 1. El tiempo de validez de la oferta es de treinta (30) días. 2. El Laboratorio de Metrología de la Universidad Santiago de Cali NO realiza cobro de IVA. 3. Si la propuesta es aceptada, por favor enviar orden de Compra o aprobacion por escrito o cotización firmada por la persona a cargo del servicio (en caso de no manejar orden de compra), RUT actualizado (sí es cliente nuevo) y formato orden de trabajo R-CM005 diligenciado. 4. La programación del servicio de calibración en sitio y laboratorio permanente dependerá de la disponibilidad del laboratorio, es decir que según la cantidad de servicios que se tengan agendados y estén en línea de llegada para calibración, las fechasde las calibraciones están sujetas a cambios, por actividades que impidan el normal funcionamiento del laboratorio, inconvenientes presentados durante el servicio o acontecimientos externos (terremotos, atentados, robos entre otros). 5. Los viáticos relacionan traslado de equipos patrones, personal técnico, alimentación y hospedaje. Estos están sujetos a cambios, por novedades presentadas en la prestación del mismo (como la disponibilidad de equipos, estado del equipo), para calibraciones en sitio solo bajo el proceso de calibración se podrá determinar si el instrumento es apto , en caso contrario se le informará al cliente. 6. El Punto Adicional en Temperatura y Humedad tiene un costo de $ 55.000.
A59: Nota A: El formato orden de trabajo R-CM005 debe ser diligenciado, para poder dar inicio al proceso de calibración.
A60: Nota B: Por favor tener en cuenta que el pago acordado dentro de la cotización debe ser cumplido, si usted no está de acuerdo antes de realizar el servicio deberá informar por escrito, de lo contrario cualquier retraso generará un interés por mora del 2,16% sobre el total de la factura.
A61: Nota C: El Laboratorio No realiza mantenimiento, ajuste y desmonte de equipos.
A62: Nota D: El plazo de entrega para el instrumento es de cinco (5) días hábiles, contados a partir de la recepción del equipo y del formato orden de trabajo R-CM005 debidamente diligenciado. Este tiempo puede variar teniendo en cuenta la cantidad de servicios que se tengan agendados previamente, la hora de llegada de los instrumentos a nuestras instalaciones y que los equipos deben contar con las óptimas condiciones de funcionamiento, deben incluir los accesorios (cables, sensores, transductores, baterías, software, entre otros) Para los equipos de tempertaratura ambiental y humedad el tiempo para la entrega sera de (8) dias habiles.
A63: Nota E: El certificado o reporte de resultados será entregado en un plazo de Tres (3) días hábiles, después de realizadas las calibraciones y verificada la cancelación del servicio.
A64: Nota G: Para instrumentos de pesaje de funcionamiento no automático, con un solo punto de apoyo o que su plataforma no permita la ubicación de las pesas, no se le realizara la prueba de excentricidad.
A65: Nota H: Los certificados de calibración serán enviados al correo que se indique en el formato orden de trabajo R-CM005, con firma digital y en formato (PDF).
A66: Nota I: En caso de que no se especifique los puntos de calibración en las magnitudes de Masa y presión el laboratorio de Metrología de la Universidad Santiago de Cali podrá realizar la asignación de acuerdo a : 1. Magnitud de Presión: Se establece al menos 5 puntos de calibración para la magnitud de presión. Estos puntos estarán regularmente espaciados desde el 10% hasta el 100% del intervalo de medición del equipo. 2. Magnitud de Masa: (instrumentos de pesaje), se establecerán 10 puntos de calibración. Estos puntos abarcarán desde la carga mínima hasta la carga máxima especificada para los instrumentos sujetos a calibración.
...

Sheet Tarifas
C1: UNIVERSIDAD SANTIAGO DE CALI DIRECCIÓN GENERAL DE LABORATORIOS Calle 5 Carrera 62 Campus Pampalinda LABORATORIO DE METROLOGÍA Bloque 4 Piso 1 Laboratorio 4129. PBX: 5183000 Ext. 9093- 9092 Celular: 314 8901580 E-mail: labmetrologia@usc.edu.co / comercialmetrologia@usc.edu.co
C5: TARIFAS
C6: EQUIPO | D6: MAGNITUD A CALIBRAR | E6: MÉTODO/ PROCEDIMIENTO | F6: # | G6: PRECIO UNITARIO 2025 | H6: PRECIO UNITARIO 2026 | I6: PRECIO AL POR MAYOR 2025 (15%)
B7: HUMEDAD | C7: Termohigrómetros / Analógicos 20 %hr ≤ hr ≤ 80 %hr 10 °C ≤ t ≤ 40 °C (Incluye 3 puntos de calibración una variable) | D7: Temperatura (Ambiente) - Humedad relativa | E7: P-CL034 Procedimiento interno Calibración de termohigrómetros analógicos v004 de 2021-08-24 | F7: 1 | G7: 155000 | H7: =G7+(G7*0.08) -> 167400 | I7: =H7-(H7*0.15) -> 142290
C8: Termohigrómetros / Digitales 20 %hr ≤ hr ≤ 80 %hr 10 °C ≤ t ≤ 40 °C (Incluye 3 puntos de calibración por variable) | D8: Temperatura (Ambiente) - Humedad relativa | E8: Procedimiento TH-007 para calibración de medidores de condiciones ambientales de temperatura y humedad en aire, Centro Español de Metrología, edición digital 1. 2021 | F8: 2 | G8: 155000 | H8: =G8+(G8*0.08) -> 167400 | I8: =H8-(H8*0.15) -> 142290
C9: Punto adicional Termohigrómetros / Analógicos 20 %hr ≤ hr ≤ 80 %hr 10 °C ≤ t ≤ 40 °C | D9: Temperatura (Ambiente) - Humedad relativa | E9: P-CL034 Procedimiento interno Calibración de termohigrómetros analógicos v004 de 2021-08-24 | F9: 3 | G9: 50000 | H9: 50000 | I9: =H9-(H9*0.15) -> 42500
C10: Punto adicional Termohigrómetros / Digitales 20 %hr ≤ hr ≤ 80 %hr 10 °C ≤ t ≤ 40 °C | D10: Temperatura (Ambiente) - Humedad relativa | E10: Procedimiento TH-007 para calibración de medidores de condiciones ambientales de temperatura y humedad en aire, Centro Español de Metrología, edición digital 1. 2021 | F10: 4 | G10: 50000 | H10: 50000 | I10: =H10-(H10*0.15) -> 42500
B11: TEMPERATURA | C11: Punto adicional Termómetros digitales con sensor termopar, RTD, termómetros digitales con sonda o punzón - 30 °C ≤ t ≤ 150 °C | D11: Temperatura | E11: Procedimiento TH-001 para la calibración de termómetros digitales (de lectura directa) por comparación, Centro Español de Metrología, edición digital 2.2021 | F11: 5 | G11: 50000 | H11: 50000 | I11: =H11-(H11*0.15) -> 42500
C12: Punto adicional Termómetros de indicación analógica sonda o punzón - 30 °C ≤ t ≤ 150 °C | D12: Temperatura | E12: Nordtest Method Thermometer, contact direct reading: Calibration NT VVS 103 Approved 1994-09. | F12: 6 | G12: 50000 | H12: 50000 | I12: =H12-(H12*0.15) -> 42500
C13: Termómetros digitales con sensor termopar, RTD, termómetros digitales con sonda o punzón - 30 °C ≤ t ≤ 150 °C (Incluye 3 puntos de calibración) | D13: Temperatura | E13: Procedimiento TH-001 para la calibración de termómetros digitales (de lectura directa) por comparación, Centro Español de Metrología, edición digital 2.2021 | F13: 7 | G13: 145000 | H13: =G13+(G13*0.08) -> 156600 | I13: =H13-(H13*0.15) -> 133110
C14: Termómetros de indicación analógica sonda o punzón - 30 °C ≤ t ≤ 150 °C (3 puntos de calibración) | D14: Temperatura | E14: Nordtest Method Thermometer, contact direct reading: Calibration NT VVS 103 Approved 1994-09. | F14: 8 | G14: 135000 | H14: =G14+(G14*0.08) -> 145800 | I14: =H14-(H14*0.15) -> 123930
B15: PRESION | C15: Manómetros analógicos y digitales Clase de exactitud ≥ 0,5 % de escala completa. (-10 psi ≤ p ≤ 0 psi) | D15: Presión | E15: Procedimiento ME-003 para la calibración de manómetros, vacuómetros y manovacuómetros, Centro Español de Metrologia, Edición Digital 3, 2019. | F15: 9 | G15: 105000 | H15: 105000 | I15: =H15-(H15*0.15) -> 89250
C16: Manómetros analógicos y digitales Clase de exactitud ≥ 0,05 % de escala completa. (0 psi < p ≤ 50 psi) | D16: Presión | E16: Procedimiento ME-003 para la calibración de manómetros, vacuómetros y manovacuómetros, Centro Español de Metrologia, Edición Digital 3, 2019. | F16: 10 | G16: 105000 | H16: 105000 | I16: =H16-(H16*0.15) -> 89250
C17: Manómetros analógicos y digitales Clase de exactitud ≥ 0,05 % de escala completa. (50 psi < p ≤ 300 psi) | D17: Presión | E17: Procedimiento ME-003 para la calibración de manómetros, vacuómetros y manovacuómetros, Centro Español de Metrologia, Edición Digital 3, 2019. | F17: 11 | G17: 105000 | H17: 105000 | I17: =H17-(H17*0.15) -> 89250
C18: Manómetros analógicos y digitales Clase de exactitud ≥ 0,05 % de escala completa. (300 psi < p ≤ 1000 psi) | D18: Presión | E18: Procedimiento ME-003 para la calibración de manómetros, vacuómetros y manovacuómetros, Centro Español de Metrologia, Edición Digital 3, 2019. | F18: 12 | G18: 150000 | H18: 105000 | I18: =H18-(H18*0.15) -> 89250
C19: Esfigmomanómetros mecánicos no invasivos analógicos 0 kPa ≤ p ≤ 40 kPa (0 mmHg ≤ p ≤ 300 mmHg) (incluye 7 puntos de calibración) | D19: Presión | E19: OIML R148-2 Non-invasive non-automated sphygmomanometers, Edition 2020, Numerales 1 y 10. | F19: 13 | G19: 95000 | H19: 95000 | I19: =H19-(H19*0.15) -> 80750
B20: MASA | C20: Instrumentos de pesaje de funcionamiento no automático con d ≥ 0,01 mg 0 g < m ≤ 220 g (incluye 11 puntos de calibración) | D20: Masa | E20: Guía para la calibración de instrumentos para pesar de funcionamiento no automático, SIM MWG7/cg-01/v.00. 2009. | F20: 14 | G20: 225000 | H20: =G20+(G20*0.08) -> 243000 | I20: =H20-(H20*0.15) -> 206550
C21: Instrumentos de pesaje de funcionamiento no automático con d ≥ 10 mg 220 g < m ≤ 5000 g (incluye 11 puntos de calibración) | D21: Masa | E21: Guía para la calibración de instrumentos para pesar de funcionamiento no automático, SIM MWG7/cg-01/v.00. 2009. | F21: 15 | G21: 188000 | H21: =G21+(G21*0.08) -> 203040 | I21: =H21-(H21*0.15) -> 172584
C22: Instrumentos de pesaje de funcionamiento no automático con d ≥ 0,1 g 5000 g < m ≤ 34 kg (incluye 11 puntos de calibración) | D22: Masa | E22: Guía para la calibración de instrumentos para pesar de funcionamiento no automático, SIM MWG7/cg-01/v.00.2009 | F22: 16 | G22: 188000 | H22: =G22+(G22*0.08) -> 203040 | I22: =H22-(H22*0.15) -> 172584
C23: Instrumentos de pesaje de funcionamiento no automático con d ≥ 10 g 34 kg < m ≤ 150 kg (incluye 11 puntos de calibración) | D23: Masa | E23: Guía para la calibración de instrumentos para pesar de funcionamiento no automático, SIM MWG7/cg-01/v.00.2009 | F23: 17 | G23: 188000 | H23: =G23+(G23*0.1) -> 206800 | I23: =H23-(H23*0.15) -> 175780
C24: Instrumentos de pesaje de funcionamiento no automático con d ≥ 50 g 150 kg < m ≤ 500 kg (incluye 11 puntos de calibración) | D24: Masa | E24: Guía para la calibración de instrumentos para pesar de funcionamiento no automático, SIM MWG7/cg-01/v.00.2009 | F24: 18 | G24: 188000 | H24: =G24+(G24*0.15) -> 216200 | I24: =H24-(H24*0.15) -> 183770
C25: Instrumentos de pesaje de funcionamiento no automático con d ≥ 0,1 kg 500 kg < m ≤ 1000 kg (incluye 11 puntos de calibración) | D25: Masa | E25: Guía para la calibración de instrumentos para pesar de funcionamiento no automático, SIM MWG7/cg-01/v.00.2009 | F25: 19 | G25: Por definir | H25: =G25+(G25*0.08) -> #VALUE! | I25: =H25-(H25*0.15) -> #VALUE!
B26: No Acreditado | C26: Agitadores de Mazzini | D26: Velocidad Angular (RPM) | E26: Procedimiento Interno | F26: 20 | G26: 98000 | H26: =G26+(G26*0.05) -> 102900 | I26: =H26-(H26*0.15) -> 87465
C27: Arco En C | D27: kV, tiempo, kV emitido | E27: Procedimiento Interno | F27: 21 | G27: 445000 | H27: =G27+(G27*0.05) -> 467250 | I27: =H27-(H27*0.15) -> 397162.5
C28: Aspiradores De Vacío (Succionador) | D28: Presión Negativa. | E28: Procedimiento Interno | F28: 22 | G28: 115000 | H28: =G28+(G28*0.05) -> 120750 | I28: =H28-(H28*0.15) -> 102637.5
C29: Pulsoxímetro O Monitor De Saturación De Oxigeno | D29: % SpO2 - Frecuencia Cardíaca. | E29: Procedimiento Interno | F29: 23 | G29: 82000 | H29: =G29+(G29*0.05) -> 86100 | I29: =H29-(H29*0.15) -> 73185
C30: Banda de esfuerzo | D30: Frecuencia Cardíaca - NIBP- % SpO2 | E30: Procedimiento Interno | F30: 24 | G30: 120000 | H30: =G30+(G30*0.05) -> 126000 | I30: =H30-(H30*0.15) -> 107100
C31: Baño Serológico - Baño de Maria | D31: Temperatura (4 puntos) | E31: Procedimiento Interno | F31: 25 | G31: 110000 | H31: =G31+(G31*0.05) -> 115500 | I31: =H31-(H31*0.15) -> 98175
C32: Blender | D32: Concentración de O2 | E32: Procedimiento Interno | F32: 26 | G32: 110000 | H32: =G32+(G32*0.05) -> 115500 | I32: =H32-(H32*0.15) -> 98175
C33: Bomba de infusión | D33: Volumen - Flujo | E33: Procedimiento Interno | F33: 27 | G33: 138000 | H33: =G33+(G33*0.05) -> 144900 | I33: =H33-(H33*0.15) -> 123165
C34: Calentador de Liquidos | D34: Temperatura | E34: Procedimiento Interno | F34: 28 | G34: 95000 | H34: =G34+(G34*0.05) -> 99750 | I34: =H34-(H34*0.15) -> 84787.5
C35: Calefactor de manta térmica | D35: Temperatura | E35: Procedimiento Interno | F35: 29 | G35: 95000 | H35: =G35+(G35*0.05) -> 99750 | I35: =H35-(H35*0.15) -> 84787.5
C36: Criostato | D36: Temperatura | E36: Procedimiento Interno | F36: 30 | G36: 225000 | H36: =G36+(G36*0.05) -> 236250 | I36: =H36-(H36*0.15) -> 200812.5
C37: Capnógrafo | D37: CO2 - %SpO2 | E37: Procedimiento Interno | F37: 31 | G37: 180000 | H37: =G37+(G37*0.05) -> 189000 | I37: =H37-(H37*0.15) -> 160650
C38: Amalgamador | D38: Revoluciones por minuto( RPM) | E38: Procedimiento Interno | F38: 32 | G38: 120000 | H38: =G38+(G38*0.05) -> 126000 | I38: =H38-(H38*0.15) -> 107100
... C70: Espirómetro | D70: Volumen - Flujo | E70: Procedimiento Interno | F70: 64 | G70: 180000 | H70: =G70+(G70*0.05) -> 189000 | I70: =H70-(H70*0.15) -> 160650
C71: Cuna De Calor Radiante | D71: Temperatura | E71: Procedimiento Interno | F71: 65 | G71: $ 172.500 | H71: =G71+(G71*0.05) -> 181125 | I71: =H71-(H71*0.15) -> 153956.25
C72: Lámparas De Fotocurado | D72: mW/cm2 | E72: Procedimiento Interno | F72: 66 | G72: 117000 | H72: =G72+(G72*0.05) -> 122850 | I72: =H72-(H72*0.15) -> 104422.5
C73: Lámpara De Fototerapia | D73: μw/Cm2 | E73: Procedimiento Interno | F73: 67 | G73: 140000 | H73: =G73+(G73*0.05) -> 147000 | I73: =H73-(H73*0.15) -> 124950
C74: Máquina De Anestesia (Sin Vaporizadores) (Incluido Ventilador) | D74: Volumen - Tiempo - Frecuencia - Presión – Flujo. | E74: Procedimiento Interno | F74: 68 | G74: 480000 | H74: =G74+(G74*0.05) -> 504000 | I74: =H74-(H74*0.15) -> 428400
...

Sheet Control de cambios
J2: UNIVERSIDAD SANTIAGO DE CALI LABORATORIO DE METROLOGÍA
J5: Hoja para control de cambios
B9: Nombre | I9: : | J9: Formato de cotización
B10: Código | I10: : | J10: R-CM003
B12: N° Versión | E12: Fecha de cambio | J12: Descripción | X12: ¿Se realiza validación de la hoja de cálculo? | Y12: Observaciones | AH12: Aprobó
B13: 09 | E13: 45552 | J13: Se realiza modificación estableciendo la condición de acreditado según numeral 4.3.1 del RAC-3.0-03 versión 9. Se incluye cuadro para el control de cambios dentro del formato. | X13: No | Y13: N.A | AH13: Luis Miguel Burgos

Sheet Tarifas (2)
C1: UNIVERSIDAD SANTIAGO DE CALI DIRECCIÓN GENERAL DE LABORATORIOS Calle 5 Carrera 62 Campus Pampalinda LABORATORIO DE METROLOGÍA Bloque 4 Piso 1 Laboratorio 4129. PBX: 5183000 Ext. 9093- 9092 Celular: 314 8901580 E-mail: labmetrologia@usc.edu.co / comercialmetrologia@usc.edu.co
C5: TARIFAS
C6: EQUIPO | D6: MAGNITUD A CALIBRAR | E6: MÉTODO/ PROCEDIMIENTO | F6: # | G6: Precio unitario 2024 | H6: Precios al por mayor 2024
B7: HUMEDAD | C7: Termohigrómetros / Analógicos 30 %hr ≤ hr ≤ 80 %hr 10 °C ≤ t ≤ 35 °C (Incluye 3 puntos de calibración una variable) | D7: Temperatura (Ambiente) - Humedad relativa | E7: P-CL034 Procedimiento interno Calibración de termohigrómetros analógicos v004 de 2021-08-24 | F7: 1 | G7: 150000 | H7: 127500
C8: Termohigrómetros / Digitales 30 %hr ≤ hr ≤ 80 %hr 10 °C ≤ t ≤ 35 °C (Incluye 3 puntos de calibración por variable) | D8: Temperatura (Ambiente) - Humedad relativa | E8: Procedimiento TH-007 para calibración de medidores de condiciones ambientales de temperatura y humedad en aire, Centro Español de Metrología, Edición Digital 1. | F8: 2 | G8: 150000 | H8: 127500
B9: TEMPERATURA | C9: Termómetros digitales con sensor termopar, RTD, termómetros digitales con sonda o punzón - 30 °C ≤ t ≤ 150 °C (Incluye 3 puntos de calibración) | D9: Temperatura | E9: Procedimiento TH-001 para la calibración de termómetros digitales (de lectura directa) por comparación, Centro Español de Metrología, edición digital 2, 2019. | F9: 3 | G9: 140000 | H9: =G9-(G9*0.15) -> 119000
C10: Termómetros de indicación analógica sonda o punzón - 30 °C ≤ t ≤ 70 °C (3 puntos de calibración) | D10: Temperatura | E10: Nordtest Method Thermometer, contact direct reading: Calibration NT VVS 103 Approved 1994-09. | F10: 4 | G10: 130000 | H10: =G10-(G10*0.15) -> 110500
B11: PRESION | C11: Manómetros analógicos y digitales Clase de exactitud ≥ 1% de escala completa 0 kPa ≤ p ≤ 0,345 MPa (0 psi ≤ p ≤ 50 psi) (incluye 5 puntos de calibración) | D11: Presión | E11: Procedimiento ME-003 para la calibración de manómetros, vacuómetros y manovacuómetros, Centro Español de Metrologia, Edición Digital 3, 2019. | F11: 5 | G11: 100000 | H11: =G11-(G11*0.15) -> 85000
C12: Infusores de liquidos (Manómetro) Clase de exactitud ≥ 1% de escala completa 0 kPa ≤ p ≤ 0,345 MPa (0 psi ≤ p ≤ 50 psi) (incluye 5 puntos de calibración) | D12: Presión | E12: Procedimiento ME-003 para la calibración de manómetros, vacuómetros y manovacuómetros, Centro Español de Metrologia, Edición Digital 3, 2019. | F12: 6 | G12: 100000 | H12: =G12-(G12*0.15) -> 85000
C13: Manómetros analógicos y digitales Clase de exactitud ≥ 0,25% de escala completa 0,345 MPa < p ≤ 2,07 MPa (50 psi < p ≤ 300 psi) (incluye 5 puntos de calibración) | D13: Presión | E13: Procedimiento ME-003 para la calibración de manómetros, vacuómetros y manovacuómetros, Centro Español de Metrologia, Edición Digital 3, 2019. | F13: 7 | G13: 100000 | H13: =G13-(G13*0.15) -> 85000
C14: Esfigmomanómetros mecánicos no invasivos analógicos 0 kPa ≤ p ≤ 40 kPa (0 mmHg ≤ p ≤ 300 mmHg) (incluye 7 puntos de calibración) | D14: Presión | E14: OIML R148-2 Non-invasive non-automated sphygmomanometers, Edition 2020, Numerales 1 y 10. | F14: 8 | G14: 90000 | H14: =G14-(G14*0.15) -> 76500
B15: MASA | C15: Instrumentos de pesaje de funcionamiento no automático con d ≥ 0,01 mg 0 g < m ≤ 220 g (incluye 11 puntos de calibración) | D15: Masa | E15: Guía para la calibración de instrumentos para pesar de funcionamiento no automático, SIM MWG7/cg-01/v.00. 2009. | F15: 10 | G15: 220000 | H15: =G15-(G15*0.15) -> 187000
C16: Instrumentos de pesaje de funcionamiento no automático con d ≥ 10 mg 220 g < m ≤ 5 kg (incluye 11 puntos de calibración) | D16: Masa | E16: Guía para la calibración de instrumentos para pesar de funcionamiento no automático, SIM MWG7/cg-01/v.00. 2009. | F16: 11 | G16: 180000 | H16: =G16-(G16*0.15) -> 153000
C17: Instrumentos de pesaje de funcionamiento no automático con d ≥ 0,1 g 5 kg < m ≤ 300 kg (incluye 11 puntos de calibración) | D17: Masa | E17: Guía para la calibración de instrumentos para pesar de funcionamiento no automático, SIM MWG7/cg-01/v.00.2009 | F17: 12 | G17: 180000 | H17: =G17-(G17*0.15) -> 153000
B18: No Acreditado | C18: Agitadores de Mazzini | D18: Velocidad Angular (RPM) | E18: Procedimiento Interno | F18: 13 | G18: 115000 | H18: =G18-(G18*0.15) -> 97750
C19: Angiógrafo | D19: kV, tiempo, kV emitido | E19: Procedimiento Interno | F19: 14 | G19: $ 494.615 | H19: =G19-(G19*0.15) -> 420422.75
C20: Mamógrafo | D20: kV, tiempo, kV emitido | E20: Procedimiento Interno | F20: 15 | G20: $ 494.616 | H20: =G20-(G20*0.15) -> 420423.6
C21: Arco En C | D21: kV, tiempo, kV emitido | E21: Procedimiento Interno | F21: 16 | G21: $ 430.100 | H21: =G21-(G21*0.15) -> 365585
C22: Aspiradores De Vacío (Succionador) | D22: Presión Negativa. | E22: Procedimiento Interno | F22: 17 | G22: 135000 | H22: =G22-(G22*0.15) -> 114750
C23: Pulsoxímetro O Monitor De Saturación De Oxigeno | D23: % SpO2 - Frecuencia Cardíaca. | E23: Procedimiento Interno | F23: 18 | G23: 80000 | H23: =G23-(G23*0.15) -> 68000
C24: Banda de esfuerzo | D24: Frecuencia Cardíaca - NIBP- % SpO2 | E24: Procedimiento Interno | F24: 19 | G24: 120000 | H24: =G24-(G24*0.15) -> 102000
C25: Baño Serológico - Baño de Maria | D25: Temperatura (4 puntos) | E25: Procedimiento Interno | F25: 20 | G25: 110000 | H25: =G25-(G25*0.15) -> 93500
C26: Blender | D26: Concentración de O2 | E26: Procedimiento Interno | F26: 21 | G26: 106950 | H26: =G26-(G26*0.15) -> 90907.5
C27: Bomba de infusión | D27: Volumen - Flujo | E27: Procedimiento Interno | F27: 22 | G27: 135000 | H27: =G27-(G27*0.15) -> 114750
C28: Calentador de Liquidos | D28: Temperatura | E28: Procedimiento Interno | F28: 23 | G28: $ 106.950 | H28: =G28-(G28*0.15) -> 90907.5
C29: Calefactor de manta térmica | D29: Temperatura | E29: Procedimiento Interno | F29: 24 | G29: $ 106.951 | H29: =G29-(G29*0.15) -> 90908.35
C30: Criostato | D30: Temperatura | E30: Procedimiento Interno | F30: 25 | G30: 220000 | H30: =G30-(G30*0.15) -> 187000
C31: Capnógrafo | D31: CO2 - %SpO2 | E31: Procedimiento Interno | F31: 26 | G31: 177439.56 | H31: =G31-(G31*0.15) -> 150823.63
C32: Amalgamador | D32: Revoluciones por minuto( RPM) | E32: Procedimiento Interno | F32: 27 | G32: 115000 | H32: =G32-(G32*0.15) -> 97750
C33: Centrífuga - Microcentrifuga | D33: Velocidad Angular (RPM) | E33: Procedimiento Interno | F33: 28 | G33: 115000 | H33: =G33-(G33*0.15) -> 97750
C34: Compresor Vascular - Presoterapia | D34: Presión. | E34: Procedimiento Interno | F34: 29 | G34: 135700 | H34: =G34-(G34*0.15) -> 115345
C35: Concentradores de oxígeno | D35: % de O2 | E35: Procedimiento Interno | F35: 30 | G35: 130000 | H35: =G35-(G35*0.15) -> 110500
C36: Densitómetros | D36: kV, tiempo, kV emitido | E36: Procedimiento Interno | F36: 31 | G36: $ 430.100 | H36: =G36-(G36*0.15) -> 365585
C37: Descongelador de Plasma | D37: Temperatura | E37: Procedimiento Interno | F37: 32 | G37: 220000 | H37: =G37-(G37*0.15) -> 187000
C38: Desfibrilador Automático DEA | D38: Energía, Voltajes, Corrientes, Tiempos, TILT, T50-T10 | E38: Procedimiento Interno | F38: 33 | G38: 190000 | H38: =G38-(G38*0.15) -> 161500
C39: Desfibrilador Automático DEA pulsado | D39: Energía, Voltajes, Corrientes, Tiempos, TILT, T50-T10 | E39: Procedimiento Interno | F39: 34 | G39: 190000 | H39: =G39-(G39*0.15) -> 161500
C40: Desfibrilador Bifásico | D40: Frecuencia Cardiaca, Energía, Voltajes, Corrientes, Tiempos de sincronia, TILT, T50-T10 | E40: Procedimiento Interno | F40: 35 | G40: 220000 | H40: =G40-(G40*0.15) -> 187000
C41: Desfibrilador con monitor de Signos vitales | D41: Frecuencia Cardiaca, SpO2,NIBP, Energía, Voltajes, Corrientes, Tiempos de sincronia, TILT, T50-T10 | E41: Procedimiento Interno | F41: 36 | G41: 270000 | H41: =G41-(G41*0.15) -> 229500
C42: Doppler Fetal | D42: Frecuencia cardíaca fetal | E42: Procedimiento Interno | F42: 37 | G42: 135000 | H42: =G42-(G42*0.15) -> 114750
C43: Ecógrafo | D43: Longitud Vertical - Horizontal y área | E43: Procedimiento Interno | F43: 38 | G43: 500000 | H43: =G43-(G43*0.15) -> 425000
...
